Workbook

Sheet Nikes Sales Dataset - Worked f
A1: Order_ID | B1: Unique Order ID | C1: Gender_Category | D1: Product_Line | E1: Product_Name | F1: Size | G1: Size Filled | H1: Units_Sold | I1: Units Sold Filled | J1: MRP | K1: MRP Final | L1: Discount_Applied | M1: Cleaned Discount | N1: Sales Price | O1: Revenue | P1: Calculated Revenue | Q1: Order_Date | R1: Cleaned Order Date | S1: Month | T1: Year | U1: Sales_Channel | V1: Region | W1: Region corrected | X1: Profit
A2: 2000 | B2: =Nikes_Sales_Dataset___Working_file[[#This Row],[Order_ID]]&"_"&TEXT(Nikes_Sales_Dataset___Working_file[[#This Row],[Cleaned Order Date]],"yyyymmdd") -> 2000_20240309 | C2: Kids | D2: Training | E2: SuperRep Go | F2: M | G2: M | I2: =IF(ISBLANK(Nikes_Sales_Dataset___Working_file[[#This Row],[Units_Sold]]),IF(Nikes_Sales_Dataset___Working_file[[#This Row],[Profit]]<0,0,1),Nikes_Sales_Dataset___Working_file[[#This Row],[Units_Sold]]) -> 0 | K2: =IF(ISBLANK(Nikes_Sales_Dataset___Working_file[[#This Row],[MRP]]),MEDIAN(Nikes_Sales_Dataset___Working_file[[#All],[MRP]]),Nikes_Sales_Dataset___Working_file[[#This Row],[MRP]]) -> 6110.03 | L2: 0.47 | M2: =IF(ISBLANK(Nikes_Sales_Dataset___Working_file[[#This Row],[Discount_Applied]]),0,Nikes_Sales_Dataset___Working_file[[#This Row],[Discount_Applied]]) -> 0.47 | N2: =Nikes_Sales_Dataset___Working_file[[#This Row],[MRP Final]]*(1-Nikes_Sales_Dataset___Working_file[[#This Row],[Cleaned Discount]]) -> 3238.3159 | O2: 0 | P2: =Nikes_Sales_Dataset___Working_file[[#This Row],[Sales Price]]*Nikes_Sales_Dataset___Working_file[[#This Row],[Units Sold Filled]] -> 0 | Q2: 45360 | R2: =IF(ISBLANK(Nikes_Sales_Dataset___Working_file[[#This Row],[Order_Date]]),"Unknown Date",Nikes_Sales_Dataset___Working_file[[#This Row],[Order_Date]]) -> 45360 | S2: =IF(ISNUMBER(Nikes_Sales_Dataset___Working_file[[#This Row],[Cleaned Order Date]]),TEXT(Nikes_Sales_Dataset___Working_file[[#This Row],[Cleaned Order Date]],"mmm"),"Unknown") -> Mar | T2: =IF(ISNUMBER(Nikes_Sales_Dataset___Working_file[[#This Row],[Cleaned Order Date]]),TEXT(Nikes_Sales_Dataset___Working_file[[#This Row],[Cleaned Order Date]],"yyyy"),"Unknown") -> 2024 | U2: Online | V2: bengaluru | W2: Bangalore | X2: -770.45 | AB2: Size
A3: 2001 | B3: =Nikes_Sales_Dataset___Working_file[[#This Row],[Order_ID]]&"_"&TEXT(Nikes_Sales_Dataset___Working_file[[#This Row],[Cleaned Order Date]],"yyyymmdd") -> 2001_20240709 | C3: Women | D3: Soccer | E3: Tiempo Legend | F3: M | G3: M | H3: 3 | I3: =IF(ISBLANK(Nikes_Sales_Dataset___Working_file[[#This Row],[Units_Sold]]),IF(Nikes_Sales_Dataset___Working_file[[#This Row],[Profit]]<0,0,1),Nikes_Sales_Dataset___Working_file[[#This Row],[Units_Sold]]) -> 3 | J3: 4957.93 | K3: =IF(ISBLANK(Nikes_Sales_Dataset___Working_file[[#This Row],[MRP]]),MEDIAN(Nikes_Sales_Dataset___Working_file[[#All],[MRP]]),Nikes_Sales_Dataset___Working_file[[#This Row],[MRP]]) -> 4957.93 | M3: =IF(ISBLANK(Nikes_Sales_Dataset___Working_file[[#This Row],[Discount_Applied]]),0,Nikes_Sales_Dataset___Working_file[[#This Row],[Discount_Applied]]) -> 0 | N3: =Nikes_Sales_Dataset___Working_file[[#This Row],[MRP Final]]*(1-Nikes_Sales_Dataset___Working_file[[#This Row],[Cleaned Discount]]) -> 4957.93 | O3: 0 | P3: =Nikes_Sales_Dataset___Working_file[[#This Row],[Sales Price]]*Nikes_Sales_Dataset___Working_file[[#This Row],[Units Sold Filled]] -> 14873.79 | Q3: 45482 | R3: =IF(ISBLANK(Nikes_Sales_Dataset___Working_file[[#This Row],[Order_Date]]),"Unknown Date",Nikes_Sales_Dataset___Working_file[[#This Row],[Order_Date]]) -> 45482 | S3: =IF(ISNUMBER(Nikes_Sales_Dataset___Working_file[[#This Row],[Cleaned Order Date]]),TEXT(Nikes_Sales_Dataset___Working_file[[#This Row],[Cleaned Order Date]],"mmm"),"Unknown") -> Jul | T3: =IF(ISNUMBER(Nikes_Sales_Dataset___Working_file[[#This Row],[Cleaned Order Date]]),TEXT(Nikes_Sales_Dataset___Working_file[[#This Row],[Cleaned Order Date]],"yyyy"),"Unknown") -> 2024 | U3: Retail | V3: Hyd | W3: Hyderabad | X3: -112.53 | AB3: M | AC3: =COUNTIF(G:G,AB3) -> 1261
A4: 2002 | B4: =Nikes_Sales_Dataset___Working_file[[#This Row],[Order_ID]]&"_"&TEXT(Nikes_Sales_Dataset___Working_file[[#This Row],[Cleaned Order Date]],"yyyymmdd") -> 2002_Unknown Date | C4: Women | D4: Soccer | E4: Premier III | F4: M | G4: M | H4: 4 | I4: =IF(ISBLANK(Nikes_Sales_Dataset___Working_file[[#This Row],[Units_Sold]]),IF(Nikes_Sales_Dataset___Working_file[[#This Row],[Profit]]<0,0,1),Nikes_Sales_Dataset___Working_file[[#This Row],[Units_Sold]]) -> 4 | K4: =IF(ISBLANK(Nikes_Sales_Dataset___Working_file[[#This Row],[MRP]]),MEDIAN(Nikes_Sales_Dataset___Working_file[[#All],[MRP]]),Nikes_Sales_Dataset___Working_file[[#This Row],[MRP]]) -> 6110.03 | M4: =IF(ISBLANK(Nikes_Sales_Dataset___Working_file[[#This Row],[Discount_Applied]]),0,Nikes_Sales_Dataset___Working_file[[#This Row],[Discount_Applied]]) -> 0 | N4: =Nikes_Sales_Dataset___Working_file[[#This Row],[MRP Final]]*(1-Nikes_Sales_Dataset___Working_file[[#This Row],[Cleaned Discount]]) -> 6110.03 | O4: 0 | P4: =Nikes_Sales_Dataset___Working_file[[#This Row],[Sales Price]]*Nikes_Sales_Dataset___Working_file[[#This Row],[Units Sold Filled]] -> 24440.12 | R4: =IF(ISBLANK(Nikes_Sales_Dataset___Working_file[[#This Row],[Order_Date]]),"Unknown Date",Nikes_Sales_Dataset___Working_file[[#This Row],[Order_Date]]) -> Unknown Date | S4: =IF(ISNUMBER(Nikes_Sales_Dataset___Working_file[[#This Row],[Cleaned Order Date]]),TEXT(Nikes_Sales_Dataset___Working_file[[#This Row],[Cleaned Order Date]],"mmm"),"Unknown") -> Unknown | T4: =IF(ISNUMBER(Nikes_Sales_Dataset___Working_file[[#This Row],[Cleaned Order Date]]),TEXT(Nikes_Sales_Dataset___Working_file[[#This Row],[Cleaned Order Date]],"yyyy"),"Unknown") -> Unknown | U4: Retail | V4: Mumbai | W4: Mumbai | X4: 3337.34 | AB4: L | AC4: =COUNTIF(G:G,AB4) -> 666
A5: 2003 | B5: =Nikes_Sales_Dataset___Working_file[[#This Row],[Order_ID]]&"_"&TEXT(Nikes_Sales_Dataset___Working_file[[#This Row],[Cleaned Order Date]],"yyyymmdd") -> 2003_20241004 | C5: Kids | D5: Lifestyle | E5: Blazer Mid | F5: L | G5: L | I5: =IF(ISBLANK(Nikes_Sales_Dataset___Working_file[[#This Row],[Units_Sold]]),IF(Nikes_Sales_Dataset___Working_file[[#This Row],[Profit]]<0,0,1),Nikes_Sales_Dataset___Working_file[[#This Row],[Units_Sold]]) -> 1 | J5: 9673.57 | K5: =IF(ISBLANK(Nikes_Sales_Dataset___Working_file[[#This Row],[MRP]]),MEDIAN(Nikes_Sales_Dataset___Working_file[[#All],[MRP]]),Nikes_Sales_Dataset___Working_file[[#This Row],[MRP]]) -> 9673.57 | M5: =IF(ISBLANK(Nikes_Sales_Dataset___Working_file[[#This Row],[Discount_Applied]]),0,Nikes_Sales_Dataset___Working_file[[#This Row],[Discount_Applied]]) -> 0 | N5: =Nikes_Sales_Dataset___Working_file[[#This Row],[MRP Final]]*(1-Nikes_Sales_Dataset___Working_file[[#This Row],[Cleaned Discount]]) -> 9673.57 | O5: 0 | P5: =Nikes_Sales_Dataset___Working_file[[#This Row],[Sales Price]]*Nikes_Sales_Dataset___Working_file[[#This Row],[Units Sold Filled]] -> 9673.57 | Q5: 45569 | R5: =IF(ISBLANK(Nikes_Sales_Dataset___Working_file[[#This Row],[Order_Date]]),"Unknown Date",Nikes_Sales_Dataset___Working_file[[#This Row],[Order_Date]]) -> 45569 | S5: =IF(ISNUMBER(Nikes_Sales_Dataset___Working_file[[#This Row],[Cleaned Order Date]]),TEXT(Nikes_Sales_Dataset___Working_file[[#This Row],[Cleaned Order Date]],"mmm"),"Unknown") -> Oct | T5: =IF(ISNUMBER(Nikes_Sales_Dataset___Working_file[[#This Row],[Cleaned Order Date]]),TEXT(Nikes_Sales_Dataset___Working_file[[#This Row],[Cleaned Order Date]],"yyyy"),"Unknown") -> 2024 | U5: Online | V5: Pune | W5: Pune | X5: 3376.85 | AB5: XL | AC5: =COUNTIF(G:G,AB5) -> 573
A6: 2004 | B6: =Nikes_Sales_Dataset___Working_file[[#This Row],[Order_ID]]&"_"&TEXT(Nikes_Sales_Dataset___Working_file[[#This Row],[Cleaned Order Date]],"yyyymmdd") -> 2004_20240912 | C6: Kids | D6: Running | E6: React Infinity | F6: XL | G6: XL | I6: =IF(ISBLANK(Nikes_Sales_Dataset___Working_file[[#This Row],[Units_Sold]]),IF(Nikes_Sales_Dataset___Working_file[[#This Row],[Profit]]<0,0,1),Nikes_Sales_Dataset___Working_file[[#This Row],[Units_Sold]]) -> 1 | K6: =IF(ISBLANK(Nikes_Sales_Dataset___Working_file[[#This Row],[MRP]]),MEDIAN(Nikes_Sales_Dataset___Working_file[[#All],[MRP]]),Nikes_Sales_Dataset___Working_file[[#This Row],[MRP]]) -> 6110.03 | M6: =IF(ISBLANK(Nikes_Sales_Dataset___Working_file[[#This Row],[Discount_Applied]]),0,Nikes_Sales_Dataset___Working_file[[#This Row],[Discount_Applied]]) -> 0 | N6: =Nikes_Sales_Dataset___Working_file[[#This Row],[MRP Final]]*(1-Nikes_Sales_Dataset___Working_file[[#This Row],[Cleaned Discount]]) -> 6110.03 | O6: 0 | P6: =Nikes_Sales_Dataset___Working_file[[#This Row],[Sales Price]]*Nikes_Sales_Dataset___Working_file[[#This Row],[Units Sold Filled]] -> 6110.03 | Q6: 45547 | R6: =IF(ISBLANK(Nikes_Sales_Dataset___Working_file[[#This Row],[Order_Date]]),"Unknown Date",Nikes_Sales_Dataset___Working_file[[#This Row],[Order_Date]]) -> 45547 | S6: =IF(ISNUMBER(Nikes_Sales_Dataset___Working_file[[#This Row],[Cleaned Order Date]]),TEXT(Nikes_Sales_Dataset___Working_file[[#This Row],[Cleaned Order Date]],"mmm"),"Unknown") -> Sep | T6: =IF(ISNUMBER(Nikes_Sales_Dataset___Working_file[[#This Row],[Cleaned Order Date]]),TEXT(Nikes_Sales_Dataset___Working_file[[#This Row],[Cleaned Order Date]],"yyyy"),"Unknown") -> 2024 | U6: Retail | V6: Delhi | W6: Delhi | X6: 187.89 | AB6: Mode="M"
A7: 2005 | B7: =Nikes_Sales_Dataset___Working_file[[#This Row],[Order_ID]]&"_"&TEXT(Nikes_Sales_Dataset___Working_file[[#This Row],[Cleaned Order Date]],"yyyymmdd") -> 2005_Unknown Date | C7: Women | D7: Training | E7: Flex Trainer | F7: M | G7: M | H7: 1 | I7: =IF(ISBLANK(Nikes_Sales_Dataset___Working_file[[#This Row],[Units_Sold]]),IF(Nikes_Sales_Dataset___Working_file[[#This Row],[Profit]]<0,0,1),Nikes_Sales_Dataset___Working_file[[#This Row],[Units_Sold]]) -> 1 | J7: 7363.96 | K7: =IF(ISBLANK(Nikes_Sales_Dataset___Working_file[[#This Row],[MRP]]),MEDIAN(Nikes_Sales_Dataset___Working_file[[#All],[MRP]]),Nikes_Sales_Dataset___Working_file[[#This Row],[MRP]]) -> 7363.96 | M7: =IF(ISBLANK(Nikes_Sales_Dataset___Working_file[[#This Row],[Discount_Applied]]),0,Nikes_Sales_Dataset___Working_file[[#This Row],[Discount_Applied]]) -> 0 | N7: =Nikes_Sales_Dataset___Working_file[[#This Row],[MRP Final]]*(1-Nikes_Sales_Dataset___Working_file[[#This Row],[Cleaned Discount]]) -> 7363.96 | O7: 0 | P7: =Nikes_Sales_Dataset___Working_file[[#This Row],[Sales Price]]*Nikes_Sales_Dataset___Working_file[[#This Row],[Units Sold Filled]] -> 7363.96 | R7: =IF(ISBLANK(Nikes_Sales_Dataset___Working_file[[#This Row],[Order_Date]]),"Unknown Date",Nikes_Sales_Dataset___Working_file[[#This Row],[Order_Date]]) -> Unknown Date | S7: =IF(ISNUMBER(Nikes_Sales_Dataset___Working_file[[#This Row],[Cleaned Order Date]]),TEXT(Nikes_Sales_Dataset___Working_file[[#This Row],[Cleaned Order Date]],"mmm"),"Unknown") -> Unknown | T7: =IF(ISNUMBER(Nikes_Sales_Dataset___Working_file[[#This Row],[Cleaned Order Date]]),TEXT(Nikes_Sales_Dataset___Working_file[[#This Row],[Cleaned Order Date]],"yyyy"),"Unknown") -> Unknown | U7: Retail | V7: Delhi | W7: Delhi | X7: 1415.98
A8: 2006 | B8: =Nikes_Sales_Dataset___Working_file[[#This Row],[Order_ID]]&"_"&TEXT(Nikes_Sales_Dataset___Working_file[[#This Row],[Cleaned Order Date]],"yyyymmdd") -> 2006_20250604 | C8: Men | D8: Training | E8: SuperRep Go | F8: M | G8: M | I8: =IF(ISBLANK(Nikes_Sales_Dataset___Working_file[[#This Row],[Units_Sold]]),IF(Nikes_Sales_Dataset___Working_file[[#This Row],[Profit]]<0,0,1),Nikes_Sales_Dataset___Working_file[[#This Row],[Units_Sold]]) -> 1 | J8: 6819.78 | K8: =IF(ISBLANK(Nikes_Sales_Dataset___Working_file[[#This Row],[MRP]]),MEDIAN(Nikes_Sales_Dataset___Working_file[[#All],[MRP]]),Nikes_Sales_Dataset___Working_file[[#This Row],[MRP]]) -> 6819.78 | M8: =IF(ISBLANK(Nikes_Sales_Dataset___Working_file[[#This Row],[Discount_Applied]]),0,Nikes_Sales_Dataset___Working_file[[#This Row],[Discount_Applied]]) -> 0 | N8: =Nikes_Sales_Dataset___Working_file[[#This Row],[MRP Final]]*(1-Nikes_Sales_Dataset___Working_file[[#This Row],[Cleaned Discount]]) -> 6819.78 | O8: 0 | P8: =Nikes_Sales_Dataset___Working_file[[#This Row],[Sales Price]]*Nikes_Sales_Dataset___Working_file[[#This Row],[Units Sold Filled]] -> 6819.78 | Q8: 45812 | R8: =IF(ISBLANK(Nikes_Sales_Dataset___Working_file[[#This Row],[Order_Date]]),"Unknown Date",Nikes_Sales_Dataset___Working_file[[#This Row],[Order_Date]]) -> 45812 | S8: =IF(ISNUMBER(Nikes_Sales_Dataset___Working_file[[#This Row],[Cleaned Order Date]]),TEXT(Nikes_Sales_Dataset___Working_file[[#This Row],[Cleaned Order Date]],"mmm"),"Unknown") -> Jun | T8: =IF(ISNUMBER(Nikes_Sales_Dataset___Working_file[[#This Row],[Cleaned Order Date]]),TEXT(Nikes_Sales_Dataset___Working_file[[#This Row],[Cleaned Order Date]],"yyyy"),"Unknown") -> 2025 | U8: Online | V8: Bangalore | W8: Bangalore | X8: 1802.09
A9: 2007 | B9: =Nikes_Sales_Dataset___Working_file[[#This Row],[Order_ID]]&"_"&TEXT(Nikes_Sales_Dataset___Working_file[[#This Row],[Cleaned Order Date]],"yyyymmdd") -> 2007_Unknown Date | C9: Kids | D9: Training | E9: SuperRep Go | F9: M | G9: M | H9: 1 | I9: =IF(ISBLANK(Nikes_Sales_Dataset___Working_file[[#This Row],[Units_Sold]]),IF(Nikes_Sales_Dataset___Working_file[[#This Row],[Profit]]<0,0,1),Nikes_Sales_Dataset___Working_file[[#This Row],[Units_Sold]]) -> 1 | K9: =IF(ISBLANK(Nikes_Sales_Dataset___Working_file[[#This Row],[MRP]]),MEDIAN(Nikes_Sales_Dataset___Working_file[[#All],[MRP]]),Nikes_Sales_Dataset___Working_file[[#This Row],[MRP]]) -> 6110.03 | L9: 0.32 | M9: =IF(ISBLANK(Nikes_Sales_Dataset___Working_file[[#This Row],[Discount_Applied]]),0,Nikes_Sales_Dataset___Working_file[[#This Row],[Discount_Applied]]) -> 0.32 | N9: =Nikes_Sales_Dataset___Working_file[[#This Row],[MRP Final]]*(1-Nikes_Sales_Dataset___Working_file[[#This Row],[Cleaned Discount]]) -> 4154.8204 | O9: 0 | P9: =Nikes_Sales_Dataset___Working_file[[#This Row],[Sales Price]]*Nikes_Sales_Dataset___Working_file[[#This Row],[Units Sold Filled]] -> 4154.8204 | R9: =IF(ISBLANK(Nikes_Sales_Dataset___Working_file[[#This Row],[Order_Date]]),"Unknown Date",Nikes_Sales_Dataset___Working_file[[#This Row],[Order_Date]]) -> Unknown Date | S9: =IF(ISNUMBER(Nikes_Sales_Dataset___Working_file[[#This Row],[Cleaned Order Date]]),TEXT(Nikes_Sales_Dataset___Working_file[[#This Row],[Cleaned Order Date]],"mmm"),"Unknown") -> Unknown | T9: =IF(ISNUMBER(Nikes_Sales_Dataset___Working_file[[#This Row],[Cleaned Order Date]]),TEXT(Nikes_Sales_Dataset___Working_file[[#This Row],[Cleaned Order Date]],"yyyy"),"Unknown") -> Unknown | U9: Retail | V9: Bangalore | W9: Bangalore | X9: 2928.36
A10: 2008 | B10: =Nikes_Sales_Dataset___Working_file[[#This Row],[Order_ID]]&"_"&TEXT(Nikes_Sales_Dataset___Working_file[[#This Row],[Cleaned Order Date]],"yyyymmdd") -> 2008_20241011 | C10: Women | D10: Soccer | E10: Premier III | F10: 11 | G10: L | H10: -1 | I10: =IF(ISBLANK(Nikes_Sales_Dataset___Working_file[[#This Row],[Units_Sold]]),IF(Nikes_Sales_Dataset___Working_file[[#This Row],[Profit]]<0,0,1),Nikes_Sales_Dataset___Working_file[[#This Row],[Units_Sold]]) -> -1 | K10: =IF(ISBLANK(Nikes_Sales_Dataset___Working_file[[#This Row],[MRP]]),MEDIAN(Nikes_Sales_Dataset___Working_file[[#All],[MRP]]),Nikes_Sales_Dataset___Working_file[[#This Row],[MRP]]) -> 6110.03 | M10: =IF(ISBLANK(Nikes_Sales_Dataset___Working_file[[#This Row],[Discount_Applied]]),0,Nikes_Sales_Dataset___Working_file[[#This Row],[Discount_Applied]]) -> 0 | N10: =Nikes_Sales_Dataset___Working_file[[#This Row],[MRP Final]]*(1-Nikes_Sales_Dataset___Working_file[[#This Row],[Cleaned Discount]]) -> 6110.03 | O10: 0 | P10: =Nikes_Sales_Dataset___Working_file[[#This Row],[Sales Price]]*Nikes_Sales_Dataset___Working_file[[#This Row],[Units Sold Filled]] -> -6110.03 | Q10: 45576 | R10: =IF(ISBLANK(Nikes_Sales_Dataset___Working_file[[#This Row],[Order_Date]]),"Unknown Date",Nikes_Sales_Dataset___Working_file[[#This Row],[Order_Date]]) -> 45576 | S10: =IF(ISNUMBER(Nikes_Sales_Dataset___Working_file[[#This Row],[Cleaned Order Date]]),TEXT(Nikes_Sales_Dataset___Working_file[[#This Row],[Cleaned Order Date]],"mmm"),"Unknown") -> Oct | T10: =IF(ISNUMBER(Nikes_Sales_Dataset___Working_file[[#This Row],[Cleaned Order Date]]),TEXT(Nikes_Sales_Dataset___Working_file[[#This Row],[Cleaned Order Date]],"yyyy"),"Unknown") -> 2024 | U10: Online | V10: Hyderabad | W10: Hyderabad | X10: -731.18
A11: 2009 | B11: =Nikes_Sales_Dataset___Working_file[[#This Row],[Order_ID]]&"_"&TEXT(Nikes_Sales_Dataset___Working_file[[#This Row],[Cleaned Order Date]],"yyyymmdd") -> 2009_Unknown Date | C11: Men | D11: Soccer | E11: Mercurial Superfly | F11: M | G11: M | H11: 4 | I11: =IF(ISBLANK(Nikes_Sales_Dataset___Working_file[[#This Row],[Units_Sold]]),IF(Nikes_Sales_Dataset___Working_file[[#This Row],[Profit]]<0,0,1),Nikes_Sales_Dataset___Working_file[[#This Row],[Units_Sold]]) -> 4 | K11: =IF(ISBLANK(Nikes_Sales_Dataset___Working_file[[#This Row],[MRP]]),MEDIAN(Nikes_Sales_Dataset___Working_file[[#All],[MRP]]),Nikes_Sales_Dataset___Working_file[[#This Row],[MRP]]) -> 6110.03 | M11: =IF(ISBLANK(Nikes_Sales_Dataset___Working_file[[#This Row],[Discount_Applied]]),0,Nikes_Sales_Dataset___Working_file[[#This Row],[Discount_Applied]]) -> 0 | N11: =Nikes_Sales_Dataset___Working_file[[#This Row],[MRP Final]]*(1-Nikes_Sales_Dataset___Working_file[[#This Row],[Cleaned Discount]]) -> 6110.03 | O11: 0 | P11: =Nikes_Sales_Dataset___Working_file[[#This Row],[Sales Price]]*Nikes_Sales_Dataset___Working_file[[#This Row],[Units Sold Filled]] -> 24440.12 | R11: =IF(ISBLANK(Nikes_Sales_Dataset___Working_file[[#This Row],[Order_Date]]),"Unknown Date",Nikes_Sales_Dataset___Working_file[[#This Row],[Order_Date]]) -> Unknown Date | S11: =IF(ISNUMBER(Nikes_Sales_Dataset___Working_file[[#This Row],[Cleaned Order Date]]),TEXT(Nikes_Sales_Dataset___Working_file[[#This Row],[Cleaned Order Date]],"mmm"),"Unknown") -> Unknown | T11: =IF(ISNUMBER(Nikes_Sales_Dataset___Working_file[[#This Row],[Cleaned Order Date]]),TEXT(Nikes_Sales_Dataset___Working_file[[#This Row],[Cleaned Order Date]],"yyyy"),"Unknown") -> Unknown | U11: Online | V11: Pune | W11: Pune | X11: 3929.61
A12: 2010 | B12: =Nikes_Sales_Dataset___Working_file[[#This Row],[Order_ID]]&"_"&TEXT(Nikes_Sales_Dataset___Working_file[[#This Row],[Cleaned Order Date]],"yyyymmdd") -> 2010_20250116 | C12: Kids | D12: Lifestyle | E12: Waffle One | F12: L | G12: L | H12: 1 | I12: =IF(ISBLANK(Nikes_Sales_Dataset___Working_file[[#This Row],[Units_Sold]]),IF(Nikes_Sales_Dataset___Working_file[[#This Row],[Profit]]<0,0,1),Nikes_Sales_Dataset___Working_file[[#This Row],[Units_Sold]]) -> 1 | J12: 7949.83 | K12: =IF(ISBLANK(Nikes_Sales_Dataset___Working_file[[#This Row],[MRP]]),MEDIAN(Nikes_Sales_Dataset___Working_file[[#All],[MRP]]),Nikes_Sales_Dataset___Working_file[[#This Row],[MRP]]) -> 7949.83 | M12: =IF(ISBLANK(Nikes_Sales_Dataset___Working_file[[#This Row],[Discount_Applied]]),0,Nikes_Sales_Dataset___Working_file[[#This Row],[Discount_Applied]]) -> 0 | N12: =Nikes_Sales_Dataset___Working_file[[#This Row],[MRP Final]]*(1-Nikes_Sales_Dataset___Working_file[[#This Row],[Cleaned Discount]]) -> 7949.83 | O12: 0 | P12: =Nikes_Sales_Dataset___Working_file[[#This Row],[Sales Price]]*Nikes_Sales_Dataset___Working_file[[#This Row],[Units Sold Filled]] -> 7949.83 | Q12: 45673 | R12: =IF(ISBLANK(Nikes_Sales_Dataset___Working_file[[#This Row],[Order_Date]]),"Unknown Date",Nikes_Sales_Dataset___Working_file[[#This Row],[Order_Date]]) -> 45673 | S12: =IF(ISNUMBER(Nikes_Sales_Dataset___Working_file[[#This Row],[Cleaned Order Date]]),TEXT(Nikes_Sales_Dataset___Working_file[[#This Row],[Cleaned Order Date]],"mmm"),"Unknown") -> Jan | T12: =IF(ISNUMBER(Nikes_Sales_Dataset___Working_file[[#This Row],[Cleaned Order Date]]),TEXT(Nikes_Sales_Dataset___Working_file[[#This Row],[Cleaned Order Date]],"yyyy"),"Unknown") -> 2025 | U12: Online | V12: Pune | W12: Pune | X12: 1965.56
A13: 2011 | B13: =Nikes_Sales_Dataset___Working_file[[#This Row],[Order_ID]]&"_"&TEXT(Nikes_Sales_Dataset___Working_file[[#This Row],[Cleaned Order Date]],"yyyymmdd") -> 2011_Unknown Date | C13: Women | D13: Training | E13: Flex Trainer | F13: L | G13: L | H13: -1 | I13: =IF(ISBLANK(Nikes_Sales_Dataset___Working_file[[#This Row],[Units_Sold]]),IF(Nikes_Sales_Dataset___Working_file[[#This Row],[Profit]]<0,0,1),Nikes_Sales_Dataset___Working_file[[#This Row],[Units_Sold]]) -> -1 | J13: 9586.08 | K13: =IF(ISBLANK(Nikes_Sales_Dataset___Working_file[[#This Row],[MRP]]),MEDIAN(Nikes_Sales_Dataset___Working_file[[#All],[MRP]]),Nikes_Sales_Dataset___Working_file[[#This Row],[MRP]]) -> 9586.08 | M13: =IF(ISBLANK(Nikes_Sales_Dataset___Working_file[[#This Row],[Discount_Applied]]),0,Nikes_Sales_Dataset___Working_file[[#This Row],[Discount_Applied]]) -> 0 | N13: =Nikes_Sales_Dataset___Working_file[[#This Row],[MRP Final]]*(1-Nikes_Sales_Dataset___Working_file[[#This Row],[Cleaned Discount]]) -> 9586.08 | O13: 0 | P13: =Nikes_Sales_Dataset___Working_file[[#This Row],[Sales Price]]*Nikes_Sales_Dataset___Working_file[[#This Row],[Units Sold Filled]] -> -9586.08 | R13: =IF(ISBLANK(Nikes_Sales_Dataset___Working_file[[#This Row],[Order_Date]]),"Unknown Date",Nikes_Sales_Dataset___Working_file[[#This Row],[Order_Date]]) -> Unknown Date | S13: =IF(ISNUMBER(Nikes_Sales_Dataset___Working_file[[#This Row],[Cleaned Order Date]]),TEXT(Nikes_Sales_Dataset___Working_file[[#This Row],[Cleaned Order Date]],"mmm"),"Unknown") -> Unknown | T13: =IF(ISNUMBER(Nikes_Sales_Dataset___Working_file[[#This Row],[Cleaned Order Date]]),TEXT(Nikes_Sales_Dataset___Working_file[[#This Row],[Cleaned Order Date]],"yyyy"),"Unknown") -> Unknown | U13: Retail | V13: Hyd | W13: Hyderabad | X13: 1667.08
A14: 2018 | B14: =Nikes_Sales_Dataset___Working_file[[#This Row],[Order_ID]]&"_"&TEXT(Nikes_Sales_Dataset___Working_file[[#This Row],[Cleaned Order Date]],"yyyymmdd") -> 2018_20241113 | C14: Kids | D14: Lifestyle | E14: Blazer Mid | G14: M | H14: -1 | I14: =IF(ISBLANK(Nikes_Sales_Dataset___Working_file[[#This Row],[Units_Sold]]),IF(Nikes_Sales_Dataset___Working_file[[#This Row],[Profit]]<0,0,1),Nikes_Sales_Dataset___Working_file[[#This Row],[Units_Sold]]) -> -1 | K14: =IF(ISBLANK(Nikes_Sales_Dataset___Working_file[[#This Row],[MRP]]),MEDIAN(Nikes_Sales_Dataset___Working_file[[#All],[MRP]]),Nikes_Sales_Dataset___Working_file[[#This Row],[MRP]]) -> 6110.03 | L14: 0.86 | M14: =IF(ISBLANK(Nikes_Sales_Dataset___Working_file[[#This Row],[Discount_Applied]]),0,Nikes_Sales_Dataset___Working_file[[#This Row],[Discount_Applied]]) -> 0.86 | N14: =Nikes_Sales_Dataset___Working_file[[#This Row],[MRP Final]]*(1-Nikes_Sales_Dataset___Working_file[[#This Row],[Cleaned Discount]]) -> 855.4042 | O14: 0 | P14: =Nikes_Sales_Dataset___Working_file[[#This Row],[Sales Price]]*Nikes_Sales_Dataset___Working_file[[#This Row],[Units Sold Filled]] -> -855.4042 | Q14: 45609 | R14: =IF(ISBLANK(Nikes_Sales_Dataset___Working_file[[#This Row],[Order_Date]]),"Unknown Date",Nikes_Sales_Dataset___Working_file[[#This Row],[Order_Date]]) -> 45609 | S14: =IF(ISNUMBER(Nikes_Sales_Dataset___Working_file[[#This Row],[Cleaned Order Date]]),TEXT(Nikes_Sales_Dataset___Working_file[[#This Row],[Cleaned Order Date]],"mmm"),"Unknown") -> Nov | T14: =IF(ISNUMBER(Nikes_Sales_Dataset___Working_file[[#This Row],[Cleaned Order Date]]),TEXT(Nikes_Sales_Dataset___Working_file[[#This Row],[Cleaned Order Date]],"yyyy"),"Unknown") -> 2024 | U14: Online | V14: Delhi | W14: Delhi | X14: 2109.48
A15: 2013 | B15: =Nikes_Sales_Dataset___Working_file[[#This Row],[Order_ID]]&"_"&TEXT(Nikes_Sales_Dataset___Working_file[[#This Row],[Cleaned Order Date]],"yyyymmdd") -> 2013_20240919 | C15: Kids | D15: Training | E15: SuperRep Go | G15: M | I15: =IF(ISBLANK(Nikes_Sales_Dataset___Working_file[[#This Row],[Units_Sold]]),IF(Nikes_Sales_Dataset___Working_file[[#This Row],[Profit]]<0,0,1),Nikes_Sales_Dataset___Working_file[[#This Row],[Units_Sold]]) -> 1 | J15: 9671.05 | K15: =IF(ISBLANK(Nikes_Sales_Dataset___Working_file[[#This Row],[MRP]]),MEDIAN(Nikes_Sales_Dataset___Working_file[[#All],[MRP]]),Nikes_Sales_Dataset___Working_file[[#This Row],[MRP]]) -> 9671.05 | M15: =IF(ISBLANK(Nikes_Sales_Dataset___Working_file[[#This Row],[Discount_Applied]]),0,Nikes_Sales_Dataset___Working_file[[#This Row],[Discount_Applied]]) -> 0 | N15: =Nikes_Sales_Dataset___Working_file[[#This Row],[MRP Final]]*(1-Nikes_Sales_Dataset___Working_file[[#This Row],[Cleaned Discount]]) -> 9671.05 | O15: 0 | P15: =Nikes_Sales_Dataset___Working_file[[#This Row],[Sales Price]]*Nikes_Sales_Dataset___Working_file[[#This Row],[Units Sold Filled]] -> 9671.05 | Q15: 45554 | R15: =IF(ISBLANK(Nikes_Sales_Dataset___Working_file[[#This Row],[Order_Date]]),"Unknown Date",Nikes_Sales_Dataset___Working_file[[#This Row],[Order_Date]]) -> 45554 | S15: =IF(ISNUMBER(Nikes_Sales_Dataset___Working_file[[#This Row],[Cleaned Order Date]]),TEXT(Nikes_Sales_Dataset___Working_file[[#This Row],[Cleaned Order Date]],"mmm"),"Unknown") -> Sep | T15: =IF(ISNUMBER(Nikes_Sales_Dataset___Working_file[[#This Row],[Cleaned Order Date]]),TEXT(Nikes_Sales_Dataset___Working_file[[#This Row],[Cleaned Order Date]],"yyyy"),"Unknown") -> 2024 | U15: Online | V15: hyderbad | W15: Hyderabad | X15: 299.34
A16: 2014 | B16: =Nikes_Sales_Dataset___Working_file[[#This Row],[Order_ID]]&"_"&TEXT(Nikes_Sales_Dataset___Working_file[[#This Row],[Cleaned Order Date]],"yyyymmdd") -> 2014_20250412 | C16: Women | D16: Running | E16: React Infinity | F16: 11 | G16: L | I16: =IF(ISBLANK(Nikes_Sales_Dataset___Working_file[[#This Row],[Units_Sold]]),IF(Nikes_Sales_Dataset___Working_file[[#This Row],[Profit]]<0,0,1),Nikes_Sales_Dataset___Working_file[[#This Row],[Units_Sold]]) -> 0 | K16: =IF(ISBLANK(Nikes_Sales_Dataset___Working_file[[#This Row],[MRP]]),MEDIAN(Nikes_Sales_Dataset___Working_file[[#All],[MRP]]),Nikes_Sales_Dataset___Working_file[[#This Row],[MRP]]) -> 6110.03 | M16: =IF(ISBLANK(Nikes_Sales_Dataset___Working_file[[#This Row],[Discount_Applied]]),0,Nikes_Sales_Dataset___Working_file[[#This Row],[Discount_Applied]]) -> 0 | N16: =Nikes_Sales_Dataset___Working_file[[#This Row],[MRP Final]]*(1-Nikes_Sales_Dataset___Working_file[[#This Row],[Cleaned Discount]]) -> 6110.03 | O16: 0 | P16: =Nikes_Sales_Dataset___Working_file[[#This Row],[Sales Price]]*Nikes_Sales_Dataset___Working_file[[#This Row],[Units Sold Filled]] -> 0 | Q16: 45759 | R16: =IF(ISBLANK(Nikes_Sales_Dataset___Working_file[[#This Row],[Order_Date]]),"Unknown Date",Nikes_Sales_Dataset___Working_file[[#This Row],[Order_Date]]) -> 45759 | S16: =IF(ISNUMBER(Nikes_Sales_Dataset___Working_file[[#This Row],[Cleaned Order Date]]),TEXT(Nikes_Sales_Dataset___Working_file[[#This Row],[Cleaned Order Date]],"mmm"),"Unknown") -> Apr | T16: =IF(ISNUMBER(Nikes_Sales_Dataset___Working_file[[#This Row],[Cleaned Order Date]]),TEXT(Nikes_Sales_Dataset___Working_file[[#This Row],[Cleaned Order Date]],"yyyy"),"Unknown") -> 2025 | U16: Online | V16: Bangalore | W16: Bangalore | X16: -1044.4
A17: 2015 | B17: =Nikes_Sales_Dataset___Working_file[[#This Row],[Order_ID]]&"_"&TEXT(Nikes_Sales_Dataset___Working_file[[#This Row],[Cleaned Order Date]],"yyyymmdd") -> 2015_20250531 | C17: Kids | D17: Basketball | E17: Air Jordan | G17: M | I17: =IF(ISBLANK(Nikes_Sales_Dataset___Working_file[[#This Row],[Units_Sold]]),IF(Nikes_Sales_Dataset___Working_file[[#This Row],[Profit]]<0,0,1),Nikes_Sales_Dataset___Working_file[[#This Row],[Units_Sold]]) -> 1 | J17: 3285.52 | K17: =IF(ISBLANK(Nikes_Sales_Dataset___Working_file[[#This Row],[MRP]]),MEDIAN(Nikes_Sales_Dataset___Working_file[[#All],[MRP]]),Nikes_Sales_Dataset___Working_file[[#This Row],[MRP]]) -> 3285.52 | M17: =IF(ISBLANK(Nikes_Sales_Dataset___Working_file[[#This Row],[Discount_Applied]]),0,Nikes_Sales_Dataset___Working_file[[#This Row],[Discount_Applied]]) -> 0 | N17: =Nikes_Sales_Dataset___Working_file[[#This Row],[MRP Final]]*(1-Nikes_Sales_Dataset___Working_file[[#This Row],[Cleaned Discount]]) -> 3285.52 | O17: 0 | P17: =Nikes_Sales_Dataset___Working_file[[#This Row],[Sales Price]]*Nikes_Sales_Dataset___Working_file[[#This Row],[Units Sold Filled]] -> 3285.52 | Q17: 45808 | R17: =IF(ISBLANK(Nikes_Sales_Dataset___Working_file[[#This Row],[Order_Date]]),"Unknown Date",Nikes_Sales_Dataset___Working_file[[#This Row],[Order_Date]]) -> 45808 | S17: =IF(ISNUMBER(Nikes_Sales_Dataset___Working_file[[#This Row],[Cleaned Order Date]]),TEXT(Nikes_Sales_Dataset___Working_file[[#This Row],[Cleaned Order Date]],"mmm"),"Unknown") -> May | T17: =IF(ISNUMBER(Nikes_Sales_Dataset___Working_file[[#This Row],[Cleaned Order Date]]),TEXT(Nikes_Sales_Dataset___Working_file[[#This Row],[Cleaned Order Date]],"yyyy"),"Unknown") -> 2025 | U17: Retail | V17: Kolkata | W17: Kolkata | X17: 1193.21
A18: 2016 | B18: =Nikes_Sales_Dataset___Working_file[[#This Row],[Order_ID]]&"_"&TEXT(Nikes_Sales_Dataset___Working_file[[#This Row],[Cleaned Order Date]],"yyyymmdd") -> 2016_Unknown Date | C18: Women | D18: Basketball | E18: Air Jordan | F18: M | G18: M | H18: 1 | I18: =IF(ISBLANK(Nikes_Sales_Dataset___Working_file[[#This Row],[Units_Sold]]),IF(Nikes_Sales_Dataset___Working_file[[#This Row],[Profit]]<0,0,1),Nikes_Sales_Dataset___Working_file[[#This Row],[Units_Sold]]) -> 1 | J18: 9871.75 | K18: =IF(ISBLANK(Nikes_Sales_Dataset___Working_file[[#This Row],[MRP]]),MEDIAN(Nikes_Sales_Dataset___Working_file[[#All],[MRP]]),Nikes_Sales_Dataset___Working_file[[#This Row],[MRP]]) -> 9871.75 | L18: 0.3 | M18: =IF(ISBLANK(Nikes_Sales_Dataset___Working_file[[#This Row],[Discount_Applied]]),0,Nikes_Sales_Dataset___Working_file[[#This Row],[Discount_Applied]]) -> 0.3 | N18: =Nikes_Sales_Dataset___Working_file[[#This Row],[MRP Final]]*(1-Nikes_Sales_Dataset___Working_file[[#This Row],[Cleaned Discount]]) -> 6910.225 | O18: 6910.22 | P18: =Nikes_Sales_Dataset___Working_file[[#This Row],[Sales Price]]*Nikes_Sales_Dataset___Working_file[[#This Row],[Units Sold Filled]] -> 6910.225 | R18: =IF(ISBLANK(Nikes_Sales_Dataset___Working_file[[#This Row],[Order_Date]]),"Unknown Date",Nikes_Sales_Dataset___Working_file[[#This Row],[Order_Date]]) -> Unknown Date | S18: =IF(ISNUMBER(Nikes_Sales_Dataset___Working_file[[#This Row],[Cleaned Order Date]]),TEXT(Nikes_Sales_Dataset___Working_file[[#This Row],[Cleaned Order Date]],"mmm"),"Unknown") -> Unknown | T18: =IF(ISNUMBER(Nikes_Sales_Dataset___Working_file[[#This Row],[Cleaned Order Date]]),TEXT(Nikes_Sales_Dataset___Working_file[[#This Row],[Cleaned Order Date]],"yyyy"),"Unknown") -> Unknown | U18: Retail | V18: hyderbad | W18: Hyderabad | X18: 2452.69
A19: 2017 | B19: =Nikes_Sales_Dataset___Working_file[[#This Row],[Order_ID]]&"_"&TEXT(Nikes_Sales_Dataset___Working_file[[#This Row],[Cleaned Order Date]],"yyyymmdd") -> 2017_20250317 | C19: Women | D19: Basketball | E19: Air Jordan | F19: 9 | G19: M | H19: 4 | I19: =IF(ISBLANK(Nikes_Sales_Dataset___Working_file[[#This Row],[Units_Sold]]),IF(Nikes_Sales_Dataset___Working_file[[#This Row],[Profit]]<0,0,1),Nikes_Sales_Dataset___Working_file[[#This Row],[Units_Sold]]) -> 4 | K19: =IF(ISBLANK(Nikes_Sales_Dataset___Working_file[[#This Row],[MRP]]),MEDIAN(Nikes_Sales_Dataset___Working_file[[#All],[MRP]]),Nikes_Sales_Dataset___Working_file[[#This Row],[MRP]]) -> 6110.03 | M19: =IF(ISBLANK(Nikes_Sales_Dataset___Working_file[[#This Row],[Discount_Applied]]),0,Nikes_Sales_Dataset___Working_file[[#This Row],[Discount_Applied]]) -> 0 | N19: =Nikes_Sales_Dataset___Working_file[[#This Row],[MRP Final]]*(1-Nikes_Sales_Dataset___Working_file[[#This Row],[Cleaned Discount]]) -> 6110.03 | O19: 0 | P19: =Nikes_Sales_Dataset___Working_file[[#This Row],[Sales Price]]*Nikes_Sales_Dataset___Working_file[[#This Row],[Units Sold Filled]] -> 24440.12 | Q19: 45733 | R19: =IF(ISBLANK(Nikes_Sales_Dataset___Working_file[[#This Row],[Order_Date]]),"Unknown Date",Nikes_Sales_Dataset___Working_file[[#This Row],[Order_Date]]) -> 45733 | S19: =IF(ISNUMBER(Nikes_Sales_Dataset___Working_file[[#This Row],[Cleaned Order Date]]),TEXT(Nikes_Sales_Dataset___Working_file[[#This Row],[Cleaned Order Date]],"mmm"),"Unknown") -> Mar | T19: =IF(ISNUMBER(Nikes_Sales_Dataset___Working_file[[#This Row],[Cleaned Order Date]]),TEXT(Nikes_Sales_Dataset___Working_file[[#This Row],[Cleaned Order Date]],"yyyy"),"Unknown") -> 2025 | U19: Retail | V19: Delhi | W19: Delhi | X19: 1946.24
A20: 2018 | B20: =Nikes_Sales_Dataset___Working_file[[#This Row],[Order_ID]]&"_"&TEXT(Nikes_Sales_Dataset___Working_file[[#This Row],[Cleaned Order Date]],"yyyymmdd") -> 2018_Unknown Date | C20: Men | D20: Training | E20: Metcon 7 | F20: XL | G20: XL | H20: 0 | I20: =IF(ISBLANK(Nikes_Sales_Dataset___Working_file[[#This Row],[Units_Sold]]),IF(Nikes_Sales_Dataset___Working_file[[#This Row],[Profit]]<0,0,1),Nikes_Sales_Dataset___Working_file[[#This Row],[Units_Sold]]) -> 0 | K20: =IF(ISBLANK(Nikes_Sales_Dataset___Working_file[[#This Row],[MRP]]),MEDIAN(Nikes_Sales_Dataset___Working_file[[#All],[MRP]]),Nikes_Sales_Dataset___Working_file[[#This Row],[MRP]]) -> 6110.03 | L20: 1.17 | M20: =IF(ISBLANK(Nikes_Sales_Dataset___Working_file[[#This Row],[Discount_Applied]]),0,Nikes_Sales_Dataset___Working_file[[#This Row],[Discount_Applied]]) -> 1.17 | N20: =Nikes_Sales_Dataset___Working_file[[#This Row],[MRP Final]]*(1-Nikes_Sales_Dataset___Working_file[[#This Row],[Cleaned Discount]]) -> -1038.7051 | O20: 0 | P20: =Nikes_Sales_Dataset___Working_file[[#This Row],[Sales Price]]*Nikes_Sales_Dataset___Working_file[[#This Row],[Units Sold Filled]] -> 0 | R20: =IF(ISBLANK(Nikes_Sales_Dataset___Working_file[[#This Row],[Order_Date]]),"Unknown Date",Nikes_Sales_Dataset___Working_file[[#This Row],[Order_Date]]) -> Unknown Date | S20: =IF(ISNUMBER(Nikes_Sales_Dataset___Working_file[[#This Row],[Cleaned Order Date]]),TEXT(Nikes_Sales_Dataset___Working_file[[#This Row],[Cleaned Order Date]],"mmm"),"Unknown") -> Unknown | T20: =IF(ISNUMBER(Nikes_Sales_Dataset___Working_file[[#This Row],[Cleaned Order Date]]),TEXT(Nikes_Sales_Dataset___Working_file[[#This Row],[Cleaned Order Date]],"yyyy"),"Unknown") -> Unknown | U20: Online | V20: bengaluru | W20: Bangalore | X20: -966.89
A21: 2019 | B21: =Nikes_Sales_Dataset___Working_file[[#This Row],[Order_ID]]&"_"&TEXT(Nikes_Sales_Dataset___Working_file[[#This Row],[Cleaned Order Date]],"yyyymmdd") -> 2019_20250117 | C21: Kids | D21: Running | E21: Air Zoom | F21: 6 | G21: M | H21: 0 | I21: =IF(ISBLANK(Nikes_Sales_Dataset___Working_file[[#This Row],[Units_Sold]]),IF(Nikes_Sales_Dataset___Working_file[[#This Row],[Profit]]<0,0,1),Nikes_Sales_Dataset___Working_file[[#This Row],[Units_Sold]]) -> 0 | J21: 3424.06 | K21: =IF(ISBLANK(Nikes_Sales_Dataset___Working_file[[#This Row],[MRP]]),MEDIAN(Nikes_Sales_Dataset___Working_file[[#All],[MRP]]),Nikes_Sales_Dataset___Working_file[[#This Row],[MRP]]) -> 3424.06 | L21: 0.32 | M21: =IF(ISBLANK(Nikes_Sales_Dataset___Working_file[[#This Row],[Discount_Applied]]),0,Nikes_Sales_Dataset___Working_file[[#This Row],[Discount_Applied]]) -> 0.32 | N21: =Nikes_Sales_Dataset___Working_file[[#This Row],[MRP Final]]*(1-Nikes_Sales_Dataset___Working_file[[#This Row],[Cleaned Discount]]) -> 2328.3608 | O21: 0 | P21: =Nikes_Sales_Dataset___Working_file[[#This Row],[Sales Price]]*Nikes_Sales_Dataset___Working_file[[#This Row],[Units Sold Filled]] -> 0 | Q21: 45674 | R21: =IF(ISBLANK(Nikes_Sales_Dataset___Working_file[[#This Row],[Order_Date]]),"Unknown Date",Nikes_Sales_Dataset___Working_file[[#This Row],[Order_Date]]) -> 45674 | S21: =IF(ISNUMBER(Nikes_Sales_Dataset___Working_file[[#This Row],[Cleaned Order Date]]),TEXT(Nikes_Sales_Dataset___Working_file[[#This Row],[Cleaned Order Date]],"mmm"),"Unknown") -> Jan | T21: =IF(ISNUMBER(Nikes_Sales_Dataset___Working_file[[#This Row],[Cleaned Order Date]]),TEXT(Nikes_Sales_Dataset___Working_file[[#This Row],[Cleaned Order Date]],"yyyy"),"Unknown") -> 2025 | U21: Online | V21: Hyderabad | W21: Hyderabad | X21: 1915.24
A22: 2020 | B22: =Nikes_Sales_Dataset___Working_file[[#This Row],[Order_ID]]&"_"&TEXT(Nikes_Sales_Dataset___Working_file[[#This Row],[Cleaned Order Date]],"yyyymmdd") -> 2020_20250328 | C22: Kids | D22: Soccer | E22: Tiempo Legend | F22: L | G22: L | H22: -1 | I22: =IF(ISBLANK(Nikes_Sales_Dataset___Working_file[[#This Row],[Units_Sold]]),IF(Nikes_Sales_Dataset___Working_file[[#This Row],[Profit]]<0,0,1),Nikes_Sales_Dataset___Working_file[[#This Row],[Units_Sold]]) -> -1 | K22: =IF(ISBLANK(Nikes_Sales_Dataset___Working_file[[#This Row],[MRP]]),MEDIAN(Nikes_Sales_Dataset___Working_file[[#All],[MRP]]),Nikes_Sales_Dataset___Working_file[[#This Row],[MRP]]) -> 6110.03 | L22: 0.67 | M22: =IF(ISBLANK(Nikes_Sales_Dataset___Working_file[[#This Row],[Discount_Applied]]),0,Nikes_Sales_Dataset___Working_file[[#This Row],[Discount_Applied]]) -> 0.67 | N22: =Nikes_Sales_Dataset___Working_file[[#This Row],[MRP Final]]*(1-Nikes_Sales_Dataset___Working_file[[#This Row],[Cleaned Discount]]) -> 2016.3099 | O22: 0 | P22: =Nikes_Sales_Dataset___Working_file[[#This Row],[Sales Price]]*Nikes_Sales_Dataset___Working_file[[#This Row],[Units Sold Filled]] -> -2016.3099 | Q22: 45744 | R22: =IF(ISBLANK(Nikes_Sales_Dataset___Working_file[[#This Row],[Order_Date]]),"Unknown Date",Nikes_Sales_Dataset___Working_file[[#This Row],[Order_Date]]) -> 45744 | S22: =IF(ISNUMBER(Nikes_Sales_Dataset___Working_file[[#This Row],[Cleaned Order Date]]),TEXT(Nikes_Sales_Dataset___Working_file[[#This Row],[Cleaned Order Date]],"mmm"),"Unknown") -> Mar | T22: =IF(ISNUMBER(Nikes_Sales_Dataset___Working_file[[#This Row],[Cleaned Order Date]]),TEXT(Nikes_Sales_Dataset___Working_file[[#This Row],[Cleaned Order Date]],"yyyy"),"Unknown") -> 2025 | U22: Retail | V22: Mumbai | W22: Mumbai | X22: 439.96
A23: 2021 | B23: =Nikes_Sales_Dataset___Working_file[[#This Row],[Order_ID]]&"_"&TEXT(Nikes_Sales_Dataset___Working_file[[#This Row],[Cleaned Order Date]],"yyyymmdd") -> 2021_20241119 | C23: Men | D23: Running | E23: Free RN | F23: L | G23: L | H23: -1 | I23: =IF(ISBLANK(Nikes_Sales_Dataset___Working_file[[#This Row],[Units_Sold]]),IF(Nikes_Sales_Dataset___Working_file[[#This Row],[Profit]]<0,0,1),Nikes_Sales_Dataset___Working_file[[#This Row],[Units_Sold]]) -> -1 | J23: 7086.7 | K23: =IF(ISBLANK(Nikes_Sales_Dataset___Working_file[[#This Row],[MRP]]),MEDIAN(Nikes_Sales_Dataset___Working_file[[#All],[MRP]]),Nikes_Sales_Dataset___Working_file[[#This Row],[MRP]]) -> 7086.7 | L23: 0.66 | M23: =IF(ISBLANK(Nikes_Sales_Dataset___Working_file[[#This Row],[Discount_Applied]]),0,Nikes_Sales_Dataset___Working_file[[#This Row],[Discount_Applied]]) -> 0.66 | N23: =Nikes_Sales_Dataset___Working_file[[#This Row],[MRP Final]]*(1-Nikes_Sales_Dataset___Working_file[[#This Row],[Cleaned Discount]]) -> 2409.478 | O23: -2409.48 | P23: =Nikes_Sales_Dataset___Working_file[[#This Row],[Sales Price]]*Nikes_Sales_Dataset___Working_file[[#This Row],[Units Sold Filled]] -> -2409.478 | Q23: 45615 | R23: =IF(ISBLANK(Nikes_Sales_Dataset___Working_file[[#This Row],[Order_Date]]),"Unknown Date",Nikes_Sales_Dataset___Working_file[[#This Row],[Order_Date]]) -> 45615 | S23: =IF(ISNUMBER(Nikes_Sales_Dataset___Working_file[[#This Row],[Cleaned Order Date]]),TEXT(Nikes_Sales_Dataset___Working_file[[#This Row],[Cleaned Order Date]],"mmm"),"Unknown") -> Nov | T23: =IF(ISNUMBER(Nikes_Sales_Dataset___Working_file[[#This Row],[Cleaned Order Date]]),TEXT(Nikes_Sales_Dataset___Working_file[[#This Row],[Cleaned Order Date]],"yyyy"),"Unknown") -> 2024 | U23: Retail | V23: Hyd | W23: Hyderabad | X23: -1120.49
A24: 2022 | B24: =Nikes_Sales_Dataset___Working_file[[#This Row],[Order_ID]]&"_"&TEXT(Nikes_Sales_Dataset___Working_file[[#This Row],[Cleaned Order Date]],"yyyymmdd") -> 2022_20240924 | C24: Women | D24: Soccer | E24: Premier III | F24: M | G24: M | I24: =IF(ISBLANK(Nikes_Sales_Dataset___Working_file[[#This Row],[Units_Sold]]),IF(Nikes_Sales_Dataset___Working_file[[#This Row],[Profit]]<0,0,1),Nikes_Sales_Dataset___Working_file[[#This Row],[Units_Sold]]) -> 1 | K24: =IF(ISBLANK(Nikes_Sales_Dataset___Working_file[[#This Row],[MRP]]),MEDIAN(Nikes_Sales_Dataset___Working_file[[#All],[MRP]]),Nikes_Sales_Dataset___Working_file[[#This Row],[MRP]]) -> 6110.03 | M24: =IF(ISBLANK(Nikes_Sales_Dataset___Working_file[[#This Row],[Discount_Applied]]),0,Nikes_Sales_Dataset___Working_file[[#This Row],[Discount_Applied]]) -> 0 | N24: =Nikes_Sales_Dataset___Working_file[[#This Row],[MRP Final]]*(1-Nikes_Sales_Dataset___Working_file[[#This Row],[Cleaned Discount]]) -> 6110.03 | O24: 0 | P24: =Nikes_Sales_Dataset___Working_file[[#This Row],[Sales Price]]*Nikes_Sales_Dataset___Working_file[[#This Row],[Units Sold Filled]] -> 6110.03 | Q24: 45559 | R24: =IF(ISBLANK(Nikes_Sales_Dataset___Working_file[[#This Row],[Order_Date]]),"Unknown Date",Nikes_Sales_Dataset___Working_file[[#This Row],[Order_Date]]) -> 45559 | S24: =IF(ISNUMBER(Nikes_Sales_Dataset___Working_file[[#This Row],[Cleaned Order Date]]),TEXT(Nikes_Sales_Dataset___Working_file[[#This Row],[Cleaned Order Date]],"mmm"),"Unknown") -> Sep | T24: =IF(ISNUMBER(Nikes_Sales_Dataset___Working_file[[#This Row],[Cleaned Order Date]]),TEXT(Nikes_Sales_Dataset___Working_file[[#This Row],[Cleaned Order Date]],"yyyy"),"Unknown") -> 2024 | U24: Online | V24: Pune | W24: Pune | X24: 3427.16
A25: 2023 | B25: =Nikes_Sales_Dataset___Working_file[[#This Row],[Order_ID]]&"_"&TEXT(Nikes_Sales_Dataset___Working_file[[#This Row],[Cleaned Order Date]],"yyyymmdd") -> 2023_20250110 | C25: Men | D25: Lifestyle | E25: Waffle One | F25: M | G25: M | I25: =IF(ISBLANK(Nikes_Sales_Dataset___Working_file[[#This Row],[Units_Sold]]),IF(Nikes_Sales_Dataset___Working_file[[#This Row],[Profit]]<0,0,1),Nikes_Sales_Dataset___Working_file[[#This Row],[Units_Sold]]) -> 1 | J25: 5003.95 | K25: =IF(ISBLANK(Nikes_Sales_Dataset___Working_file[[#This Row],[MRP]]),MEDIAN(Nikes_Sales_Dataset___Working_file[[#All],[MRP]]),Nikes_Sales_Dataset___Working_file[[#This Row],[MRP]]) -> 5003.95 | M25: =IF(ISBLANK(Nikes_Sales_Dataset___Working_file[[#This Row],[Discount_Applied]]),0,Nikes_Sales_Dataset___Working_file[[#This Row],[Discount_Applied]]) -> 0 | N25: =Nikes_Sales_Dataset___Working_file[[#This Row],[MRP Final]]*(1-Nikes_Sales_Dataset___Working_file[[#This Row],[Cleaned Discount]]) -> 5003.95 | O25: 0 | P25: =Nikes_Sales_Dataset___Working_file[[#This Row],[Sales Price]]*Nikes_Sales_Dataset___Working_file[[#This Row],[Units Sold Filled]] -> 5003.95 | Q25: 45667 | R25: =IF(ISBLANK(Nikes_Sales_Dataset___Working_file[[#This Row],[Order_Date]]),"Unknown Date",Nikes_Sales_Dataset___Working_file[[#This Row],[Order_Date]]) -> 45667 | S25: =IF(ISNUMBER(Nikes_Sales_Dataset___Working_file[[#This Row],[Cleaned Order Date]]),TEXT(Nikes_Sales_Dataset___Working_file[[#This Row],[Cleaned Order Date]],"mmm"),"Unknown") -> Jan | T25: =IF(ISNUMBER(Nikes_Sales_Dataset___Working_file[[#This Row],[Cleaned Order Date]]),TEXT(Nikes_Sales_Dataset___Working_file[[#This Row],[Cleaned Order Date]],"yyyy"),"Unknown") -> 2025 | U25: Online | V25: Mumbai | W25: Mumbai | X25: 1498.37
A26: 2024 | B26: =Nikes_Sales_Dataset___Working_file[[#This Row],[Order_ID]]&"_"&TEXT(Nikes_Sales_Dataset___Working_file[[#This Row],[Cleaned Order Date]],"yyyymmdd") -> 2024_20241228 | C26: Kids | D26: Training | E26: SuperRep Go | F26: XL | G26: XL | H26: 0 | I26: =IF(ISBLANK(Nikes_Sales_Dataset___Working_file[[#This Row],[Units_Sold]]),IF(Nikes_Sales_Dataset___Working_file[[#This Row],[Profit]]<0,0,1),Nikes_Sales_Dataset___Working_file[[#This Row],[Units_Sold]]) -> 0 | K26: =IF(ISBLANK(Nikes_Sales_Dataset___Working_file[[#This Row],[MRP]]),MEDIAN(Nikes_Sales_Dataset___Working_file[[#All],[MRP]]),Nikes_Sales_Dataset___Working_file[[#This Row],[MRP]]) -> 6110.03 | L26: 0.5 | M26: =IF(ISBLANK(Nikes_Sales_Dataset___Working_file[[#This Row],[Discount_Applied]]),0,Nikes_Sales_Dataset___Working_file[[#This Row],[Discount_Applied]]) -> 0.5 | N26: =Nikes_Sales_Dataset___Working_file[[#This Row],[MRP Final]]*(1-Nikes_Sales_Dataset___Working_file[[#This Row],[Cleaned Discount]]) -> 3055.015 | O26: 0 | P26: =Nikes_Sales_Dataset___Working_file[[#This Row],[Sales Price]]*Nikes_Sales_Dataset___Working_file[[#This Row],[Units Sold Filled]] -> 0 | Q26: 45654 | R26: =IF(ISBLANK(Nikes_Sales_Dataset___Working_file[[#This Row],[Order_Date]]),"Unknown Date",Nikes_Sales_Dataset___Working_file[[#This Row],[Order_Date]]) -> 45654 | S26: =IF(ISNUMBER(Nikes_Sales_Dataset___Working_file[[#This Row],[Cleaned Order Date]]),TEXT(Nikes_Sales_Dataset___Working_file[[#This Row],[Cleaned Order Date]],"mmm"),"Unknown") -> Dec | T26: =IF(ISNUMBER(Nikes_Sales_Dataset___Working_file[[#This Row],[Cleaned Order Date]]),TEXT(Nikes_Sales_Dataset___Working_file[[#This Row],[Cleaned Order Date]],"yyyy"),"Unknown") -> 2024 | U26: Retail | V26: Bangalore | W26: Bangalore | X26: 1842.35
A27: 2025 | B27: =Nikes_Sales_Dataset___Working_file[[#This Row],[Order_ID]]&"_"&TEXT(Nikes_Sales_Dataset___Working_file[[#This Row],[Cleaned Order Date]],"yyyymmdd") -> 2025_Unknown Date | C27: Women | D27: Basketball | E27: Kyrie Flytrap | F27: M | G27: M | H27: 3 | I27: =IF(ISBLANK(Nikes_Sales_Dataset___Working_file[[#This Row],[Units_Sold]]),IF(Nikes_Sales_Dataset___Working_file[[#This Row],[Profit]]<0,0,1),Nikes_Sales_Dataset___Working_file[[#This Row],[Units_Sold]]) -> 3 | J27: 9820.5 | K27: =IF(ISBLANK(Nikes_Sales_Dataset___Working_file[[#This Row],[MRP]]),MEDIAN(Nikes_Sales_Dataset___Working_file[[#All],[MRP]]),Nikes_Sales_Dataset___Working_file[[#This Row],[MRP]]) -> 9820.5 | M27: =IF(ISBLANK(Nikes_Sales_Dataset___Working_file[[#This Row],[Discount_Applied]]),0,Nikes_Sales_Dataset___Working_file[[#This Row],[Discount_Applied]]) -> 0 | N27: =Nikes_Sales_Dataset___Working_file[[#This Row],[MRP Final]]*(1-Nikes_Sales_Dataset___Working_file[[#This Row],[Cleaned Discount]]) -> 9820.5 | O27: 0 | P27: =Nikes_Sales_Dataset___Working_file[[#This Row],[Sales Price]]*Nikes_Sales_Dataset___Working_file[[#This Row],[Units Sold Filled]] -> 29461.5 | R27: =IF(ISBLANK(Nikes_Sales_Dataset___Working_file[[#This Row],[Order_Date]]),"Unknown Date",Nikes_Sales_Dataset___Working_file[[#This Row],[Order_Date]]) -> Unknown Date | S27: =IF(ISNUMBER(Nikes_Sales_Dataset___Working_file[[#This Row],[Cleaned Order Date]]),TEXT(Nikes_Sales_Dataset___Working_file[[#This Row],[Cleaned Order Date]],"mmm"),"Unknown") -> Unknown | T27: =IF(ISNUMBER(Nikes_Sales_Dataset___Working_file[[#This Row],[Cleaned Order Date]]),TEXT(Nikes_Sales_Dataset___Working_file[[#This Row],[Cleaned Order Date]],"yyyy"),"Unknown") -> Unknown | U27: Retail | V27: Mumbai | W27: Mumbai | X27: 1900.15
A28: 2026 | B28: =Nikes_Sales_Dataset___Working_file[[#This Row],[Order_ID]]&"_"&TEXT(Nikes_Sales_Dataset___Working_file[[#This Row],[Cleaned Order Date]],"yyyymmdd") -> 2026_20240810 | C28: Kids | D28: Lifestyle | E28: Blazer Mid | F28: XL | G28: XL | H28: 1 | I28: =IF(ISBLANK(Nikes_Sales_Dataset___Working_file[[#This Row],[Units_Sold]]),IF(Nikes_Sales_Dataset___Working_file[[#This Row],[Profit]]<0,0,1),Nikes_Sales_Dataset___Working_file[[#This Row],[Units_Sold]]) -> 1 | K28: =IF(ISBLANK(Nikes_Sales_Dataset___Working_file[[#This Row],[MRP]]),MEDIAN(Nikes_Sales_Dataset___Working_file[[#All],[MRP]]),Nikes_Sales_Dataset___Working_file[[#This Row],[MRP]]) -> 6110.03 | L28: 0.16 | M28: =IF(ISBLANK(Nikes_Sales_Dataset___Working_file[[#This Row],[Discount_Applied]]),0,Nikes_Sales_Dataset___Working_file[[#This Row],[Discount_Applied]]) -> 0.16 | N28: =Nikes_Sales_Dataset___Working_file[[#This Row],[MRP Final]]*(1-Nikes_Sales_Dataset___Working_file[[#This Row],[Cleaned Discount]]) -> 5132.4252 | O28: 0 | P28: =Nikes_Sales_Dataset___Working_file[[#This Row],[Sales Price]]*Nikes_Sales_Dataset___Working_file[[#This Row],[Units Sold Filled]] -> 5132.4252 | Q28: 45514 | R28: =IF(ISBLANK(Nikes_Sales_Dataset___Working_file[[#This Row],[Order_Date]]),"Unknown Date",Nikes_Sales_Dataset___Working_file[[#This Row],[Order_Date]]) -> 45514 | S28: =IF(ISNUMBER(Nikes_Sales_Dataset___Working_file[[#This Row],[Cleaned Order Date]]),TEXT(Nikes_Sales_Dataset___Working_file[[#This Row],[Cleaned Order Date]],"mmm"),"Unknown") -> Aug | T28: =IF(ISNUMBER(Nikes_Sales_Dataset___Working_file[[#This Row],[Cleaned Order Date]]),TEXT(Nikes_Sales_Dataset___Working_file[[#This Row],[Cleaned Order Date]],"yyyy"),"Unknown") -> 2024 | U28: Retail | V28: Kolkata | W28: Kolkata | X28: 2301.64
A29: 2027 | B29: =Nikes_Sales_Dataset___Working_file[[#This Row],[Order_ID]]&"_"&TEXT(Nikes_Sales_Dataset___Working_file[[#This Row],[Cleaned Order Date]],"yyyymmdd") -> 2027_Unknown Date | C29: Men | D29: Basketball | E29: Zoom Freak | F29: XL | G29: XL | I29: =IF(ISBLANK(Nikes_Sales_Dataset___Working_file[[#This Row],[Units_Sold]]),IF(Nikes_Sales_Dataset___Working_file[[#This Row],[Profit]]<0,0,1),Nikes_Sales_Dataset___Working_file[[#This Row],[Units_Sold]]) -> 0 | K29: =IF(ISBLANK(Nikes_Sales_Dataset___Working_file[[#This Row],[MRP]]),MEDIAN(Nikes_Sales_Dataset___Working_file[[#All],[MRP]]),Nikes_Sales_Dataset___Working_file[[#This Row],[MRP]]) -> 6110.03 | L29: 0.22 | M29: =IF(ISBLANK(Nikes_Sales_Dataset___Working_file[[#This Row],[Discount_Applied]]),0,Nikes_Sales_Dataset___Working_file[[#This Row],[Discount_Applied]]) -> 0.22 | N29: =Nikes_Sales_Dataset___Working_file[[#This Row],[MRP Final]]*(1-Nikes_Sales_Dataset___Working_file[[#This Row],[Cleaned Discount]]) -> 4765.8234 | O29: 0 | P29: =Nikes_Sales_Dataset___Working_file[[#This Row],[Sales Price]]*Nikes_Sales_Dataset___Working_file[[#This Row],[Units Sold Filled]] -> 0 | R29: =IF(ISBLANK(Nikes_Sales_Dataset___Working_file[[#This Row],[Order_Date]]),"Unknown Date",Nikes_Sales_Dataset___Working_file[[#This Row],[Order_Date]]) -> Unknown Date | S29: =IF(ISNUMBER(Nikes_Sales_Dataset___Working_file[[#This Row],[Cleaned Order Date]]),TEXT(Nikes_Sales_Dataset___Working_file[[#This Row],[Cleaned Order Date]],"mmm"),"Unknown") -> Unknown | T29: =IF(ISNUMBER(Nikes_Sales_Dataset___Working_file[[#This Row],[Cleaned Order Date]]),TEXT(Nikes_Sales_Dataset___Working_file[[#This Row],[Cleaned Order Date]],"yyyy"),"Unknown") -> Unknown | U29: Online | V29: Pune | W29: Pune | X29: -138.74
A30: 2028 | B30: =Nikes_Sales_Dataset___Working_file[[#This Row],[Order_ID]]&"_"&TEXT(Nikes_Sales_Dataset___Working_file[[#This Row],[Cleaned Order Date]],"yyyymmdd") -> 2028_Unknown Date | C30: Men | D30: Training | E30: Flex Trainer | F30: 12 | G30: XL | I30: =IF(ISBLANK(Nikes_Sales_Dataset___Working_file[[#This Row],[Units_Sold]]),IF(Nikes_Sales_Dataset___Working_file[[#This Row],[Profit]]<0,0,1),Nikes_Sales_Dataset___Working_file[[#This Row],[Units_Sold]]) -> 0 | J30: 3270.23 | K30: =IF(ISBLANK(Nikes_Sales_Dataset___Working_file[[#This Row],[MRP]]),MEDIAN(Nikes_Sales_Dataset___Working_file[[#All],[MRP]]),Nikes_Sales_Dataset___Working_file[[#This Row],[MRP]]) -> 3270.23 | M30: =IF(ISBLANK(Nikes_Sales_Dataset___Working_file[[#This Row],[Discount_Applied]]),0,Nikes_Sales_Dataset___Working_file[[#This Row],[Discount_Applied]]) -> 0 | N30: =Nikes_Sales_Dataset___Working_file[[#This Row],[MRP Final]]*(1-Nikes_Sales_Dataset___Working_file[[#This Row],[Cleaned Discount]]) -> 3270.23 | O30: 0 | P30: =Nikes_Sales_Dataset___Working_file[[#This Row],[Sales Price]]*Nikes_Sales_Dataset___Working_file[[#This Row],[Units Sold Filled]] -> 0 | R30: =IF(ISBLANK(Nikes_Sales_Dataset___Working_file[[#This Row],[Order_Date]]),"Unknown Date",Nikes_Sales_Dataset___Working_file[[#This Row],[Order_Date]]) -> Unknown Date | S30: =IF(ISNUMBER(Nikes_Sales_Dataset___Working_file[[#This Row],[Cleaned Order Date]]),TEXT(Nikes_Sales_Dataset___Working_file[[#This Row],[Cleaned Order Date]],"mmm"),"Unknown") -> Unknown | T30: =IF(ISNUMBER(Nikes_Sales_Dataset___Working_file[[#This Row],[Cleaned Order Date]]),TEXT(Nikes_Sales_Dataset___Working_file[[#This Row],[Cleaned Order Date]],"yyyy"),"Unknown") -> Unknown | U30: Retail | V30: Delhi | W30: Delhi | X30: -946.86
A31: 2029 | B31: =Nikes_Sales_Dataset___Working_file[[#This Row],[Order_ID]]&"_"&TEXT(Nikes_Sales_Dataset___Working_file[[#This Row],[Cleaned Order Date]],"yyyymmdd") -> 2029_20231028 | C31: Men | D31: Training | E31: ZoomX Invincible | F31: 12 | G31: XL | H31: 0 | I31: =IF(ISBLANK(Nikes_Sales_Dataset___Working_file[[#This Row],[Units_Sold]]),IF(Nikes_Sales_Dataset___Working_file[[#This Row],[Profit]]<0,0,1),Nikes_Sales_Dataset___Working_file[[#This Row],[Units_Sold]]) -> 0 | K31: =IF(ISBLANK(Nikes_Sales_Dataset___Working_file[[#This Row],[MRP]]),MEDIAN(Nikes_Sales_Dataset___Working_file[[#All],[MRP]]),Nikes_Sales_Dataset___Working_file[[#This Row],[MRP]]) -> 6110.03 | M31: =IF(ISBLANK(Nikes_Sales_Dataset___Working_file[[#This Row],[Discount_Applied]]),0,Nikes_Sales_Dataset___Working_file[[#This Row],[Discount_Applied]]) -> 0 | N31: =Nikes_Sales_Dataset___Working_file[[#This Row],[MRP Final]]*(1-Nikes_Sales_Dataset___Working_file[[#This Row],[Cleaned Discount]]) -> 6110.03 | O31: 0 | P31: =Nikes_Sales_Dataset___Working_file[[#This Row],[Sales Price]]*Nikes_Sales_Dataset___Working_file[[#This Row],[Units Sold Filled]] -> 0 | Q31: 45227 | R31: =IF(ISBLANK(Nikes_Sales_Dataset___Working_file[[#This Row],[Order_Date]]),"Unknown Date",Nikes_Sales_Dataset___Working_file[[#This Row],[Order_Date]]) -> 45227 | S31: =IF(ISNUMBER(Nikes_Sales_Dataset___Working_file[[#This Row],[Cleaned Order Date]]),TEXT(Nikes_Sales_Dataset___Working_file[[#This Row],[Cleaned Order Date]],"mmm"),"Unknown") -> Oct | T31: =IF(ISNUMBER(Nikes_Sales_Dataset___Working_file[[#This Row],[Cleaned Order Date]]),TEXT(Nikes_Sales_Dataset___Working_file[[#This Row],[Cleaned Order Date]],"yyyy"),"Unknown") -> 2023 | U31: Online | V31: Bangalore | W31: Bangalore | X31: -185.67
A32: 2030 | B32: =Nikes_Sales_Dataset___Working_file[[#This Row],[Order_ID]]&"_"&TEXT(Nikes_Sales_Dataset___Working_file[[#This Row],[Cleaned Order Date]],"yyyymmdd") -> 2030_20250714 | C32: Men | D32: Soccer | E32: Phantom GT | F32: XL | G32: XL | I32: =IF(ISBLANK(Nikes_Sales_Dataset___Working_file[[#This Row],[Units_Sold]]),IF(Nikes_Sales_Dataset___Working_file[[#This Row],[Profit]]<0,0,1),Nikes_Sales_Dataset___Working_file[[#This Row],[Units_Sold]]) -> 0 | K32: =IF(ISBLANK(Nikes_Sales_Dataset___Working_file[[#This Row],[MRP]]),MEDIAN(Nikes_Sales_Dataset___Working_file[[#All],[MRP]]),Nikes_Sales_Dataset___Working_file[[#This Row],[MRP]]) -> 6110.03 | L32: 1.05 | M32: =IF(ISBLANK(Nikes_Sales_Dataset___Working_file[[#This Row],[Discount_Applied]]),0,Nikes_Sales_Dataset___Working_file[[#This Row],[Discount_Applied]]) -> 1.05 | N32: =Nikes_Sales_Dataset___Working_file[[#This Row],[MRP Final]]*(1-Nikes_Sales_Dataset___Working_file[[#This Row],[Cleaned Discount]]) -> -305.5015 | O32: 0 | P32: =Nikes_Sales_Dataset___Working_file[[#This Row],[Sales Price]]*Nikes_Sales_Dataset___Working_file[[#This Row],[Units Sold Filled]] -> 0 | Q32: 45852 | R32: =IF(ISBLANK(Nikes_Sales_Dataset___Working_file[[#This Row],[Order_Date]]),"Unknown Date",Nikes_Sales_Dataset___Working_file[[#This Row],[Order_Date]]) -> 45852 | S32: =IF(ISNUMBER(Nikes_Sales_Dataset___Working_file[[#This Row],[Cleaned Order Date]]),TEXT(Nikes_Sales_Dataset___Working_file[[#This Row],[Cleaned Order Date]],"mmm"),"Unknown") -> Jul | T32: =IF(ISNUMBER(Nikes_Sales_Dataset___Working_file[[#This Row],[Cleaned Order Date]]),TEXT(Nikes_Sales_Dataset___Working_file[[#This Row],[Cleaned Order Date]],"yyyy"),"Unknown") -> 2025 | U32: Retail | V32: Hyd | W32: Hyderabad | X32: -122.93
A33: 2031 | B33: =Nikes_Sales_Dataset___Working_file[[#This Row],[Order_ID]]&"_"&TEXT(Nikes_Sales_Dataset___Working_file[[#This Row],[Cleaned Order Date]],"yyyymmdd") -> 2031_20240509 | C33: Men | D33: Soccer | E33: Premier III | G33: M | H33: 4 | I33: =IF(ISBLANK(Nikes_Sales_Dataset___Working_file[[#This Row],[Units_Sold]]),IF(Nikes_Sales_Dataset___Working_file[[#This Row],[Profit]]<0,0,1),Nikes_Sales_Dataset___Working_file[[#This Row],[Units_Sold]]) -> 4 | J33: 3493.04 | K33: =IF(ISBLANK(Nikes_Sales_Dataset___Working_file[[#This Row],[MRP]]),MEDIAN(Nikes_Sales_Dataset___Working_file[[#All],[MRP]]),Nikes_Sales_Dataset___Working_file[[#This Row],[MRP]]) -> 3493.04 | L33: 0.82 | M33: =IF(ISBLANK(Nikes_Sales_Dataset___Working_file[[#This Row],[Discount_Applied]]),0,Nikes_Sales_Dataset___Working_file[[#This Row],[Discount_Applied]]) -> 0.82 | N33: =Nikes_Sales_Dataset___Working_file[[#This Row],[MRP Final]]*(1-Nikes_Sales_Dataset___Working_file[[#This Row],[Cleaned Discount]]) -> 628.7472 | O33: 2514.99 | P33: =Nikes_Sales_Dataset___Working_file[[#This Row],[Sales Price]]*Nikes_Sales_Dataset___Working_file[[#This Row],[Units Sold Filled]] -> 2514.9888 | Q33: 45421 | R33: =IF(ISBLANK(Nikes_Sales_Dataset___Working_file[[#This Row],[Order_Date]]),"Unknown Date",Nikes_Sales_Dataset___Working_file[[#This Row],[Order_Date]]) -> 45421 | S33: =IF(ISNUMBER(Nikes_Sales_Dataset___Working_file[[#This Row],[Cleaned Order Date]]),TEXT(Nikes_Sales_Dataset___Working_file[[#This Row],[Cleaned Order Date]],"mmm"),"Unknown") -> May | T33: =IF(ISNUMBER(Nikes_Sales_Dataset___Working_file[[#This Row],[Cleaned Order Date]]),TEXT(Nikes_Sales_Dataset___Working_file[[#This Row],[Cleaned Order Date]],"yyyy"),"Unknown") -> 2024 | U33: Online | V33: Delhi | W33: Delhi | X33: 350.7
A34: 2032 | B34: =Nikes_Sales_Dataset___Working_file[[#This Row],[Order_ID]]&"_"&TEXT(Nikes_Sales_Dataset___Working_file[[#This Row],[Cleaned Order Date]],"yyyymmdd") -> 2032_20250411 | C34: Women | D34: Lifestyle | E34: Blazer Mid | F34: XL | G34: XL | H34: 1 | I34: =IF(ISBLANK(Nikes_Sales_Dataset___Working_file[[#This Row],[Units_Sold]]),IF(Nikes_Sales_Dataset___Working_file[[#This Row],[Profit]]<0,0,1),Nikes_Sales_Dataset___Working_file[[#This Row],[Units_Sold]]) -> 1 | K34: =IF(ISBLANK(Nikes_Sales_Dataset___Working_file[[#This Row],[MRP]]),MEDIAN(Nikes_Sales_Dataset___Working_file[[#All],[MRP]]),Nikes_Sales_Dataset___Working_file[[#This Row],[MRP]]) -> 6110.03 | L34: 1.07 | M34: =IF(ISBLANK(Nikes_Sales_Dataset___Working_file[[#This Row],[Discount_Applied]]),0,Nikes_Sales_Dataset___Working_file[[#This Row],[Discount_Applied]]) -> 1.07 | N34: =Nikes_Sales_Dataset___Working_file[[#This Row],[MRP Final]]*(1-Nikes_Sales_Dataset___Working_file[[#This Row],[Cleaned Discount]]) -> -427.7021 | O34: 0 | P34: =Nikes_Sales_Dataset___Working_file[[#This Row],[Sales Price]]*Nikes_Sales_Dataset___Working_file[[#This Row],[Units Sold Filled]] -> -427.7021 | Q34: 45758 | R34: =IF(ISBLANK(Nikes_Sales_Dataset___Working_file[[#This Row],[Order_Date]]),"Unknown Date",Nikes_Sales_Dataset___Working_file[[#This Row],[Order_Date]]) -> 45758 | S34: =IF(ISNUMBER(Nikes_Sales_Dataset___Working_file[[#This Row],[Cleaned Order Date]]),TEXT(Nikes_Sales_Dataset___Working_file[[#This Row],[Cleaned Order Date]],"mmm"),"Unknown") -> Apr | T34: =IF(ISNUMBER(Nikes_Sales_Dataset___Working_file[[#This Row],[Cleaned Order Date]]),TEXT(Nikes_Sales_Dataset___Working_file[[#This Row],[Cleaned Order Date]],"yyyy"),"Unknown") -> 2025 | U34: Retail | V34: Mumbai | W34: Mumbai | X34: -555.16
